Workbook
Name Klimaatimpact: Tabel14[[#Headers],[CO2-nieuw (kg)]]

Sheet Methodiek
G2: Tabblad in Excel | H2: Functie binnen het rekenmodel
G3: Methodiek | H3: Bevat een toelichitng over het gebruik van het rekenmodel.
G4: Dashboard | H4: In dit blad wordt er een overzicht gegeven van de uitkomsten uit het rekenmodel die gekoppeld zijn met Bim-data.
G5: Hout, Staal, Beton, Koper, Aluminium, Bitumen | H5: Bevatten de materiaalspecifieke berekeningen voor recovery rate, CO₂-uitstoot en financiële waarde. Opgesteld opbasis van voorbeeld emlementen en volumes.
G6: Hout 2.0, Staal 2.0, Beton 2.0, Koper 2.0, Aluminium 2.0, Bitumen 2.0 | H6: Bevatten de indeling van materialen in categorieën en onderbouwingen.
G7: Hout-data, Staal-data, Beton-data, Koper-data, Aluminium-data, Bitumen-data | H7: in dit blad komt de data afkomstig uit een BIM-model, en wordt hier in een tabel genoteerd.
G8: Categorie | H8: Geeft een totaaloverzicht van de A-, B-, C- en bijzonder-indeling per materiaalsoort.
G11: Lagenda | H11: Formule
G12: Doel: | H12: Deze workbook vult ontbrekende recovery-velden in met referentie-eenheden en conservatieve aannames.
G13: Belangrijk: | H13: waar projectspecifieke hoeveelheden ontbreken, is gewerkt met 1 m3, 1 kg of 1 stuk als referentie.
G14: Praktische recovery rate (%) = | H14: =ALS.FOUT(AFRONDEN([@[Gem. score]]/5;2);0)
G15: Gem. score = | H15: Gemiddelde van Demonteerbaarheid, Materiaalconditie en Marktpotentie
G16: Hergebruik/recycling | H16: Zijn verdeeld op basis van routeadvies via onderstaande lookup-tabel.
G17: Gebaseerd op schattingen en waarnemen
G19: Routeadvies | H19: Betekenis
G20: Hergebruik | H20: Het materiaal kan grotendeels opnieuw als product of element worden toegepast.
G21: Recycling | H21: Het materiaal wordt verwerkt tot een lagere toepassing.
G22: Handmatig beoordelen | H22: Het materiaal vraagt extra controle door een expert.
G26: Eindbeoordeling dashboard | H26: Wanneer score je Ja? | I26: Wanneer score je Nee? | J26: Wanneer score je Handmatig?
G27: Financieel positief? | H27: Als de financiële marktwaarde groter is dan €0. | I27: Als de financiële marktwaarde €0 of lager is. | J27: Als de klasse Totaal, leeg of Handmatig beoordelen is.
G28: Klimaatpositief? | H28: Als het klimaat-routeadvies aangeeft dat hergebruik of recycling klimaatvriendelijker is. | I28: Als er geen klimaatvoordeel uit het model komt. | J28: Als er geen klimaatadvies is of de klasse handmatig beoordeeld moet worden.
G29: Recovery hoog? | H29: Als de PRR 70% of hoger is. | I29: Als de PRR lager dan 70% is. | J29: Als er geen PRR is of de klasse handmatig beoordeeld moet worden.
G30: Eindbeoordeling | H30: Interessant bij minimaal 2 keer Ja. | I30: Niet interessant bij 0 keer Ja. | J30: Twijfelachtig bij 1 keer Ja of Handmatig beoordelen als er te weinig betrouwbare input is.

Sheet Dashboard
A1: Dashboard sloopproject
A2: Materiaalstroom | B2: Bouwdeel uit BIM | C2: BIM-volume m³ | D2: Transport Impact | E2: Transportafstand (km) | F2: Demonteerbaarheid | G2: Materiaalconditie | H2: Marktpotentie | I2: PRR | J2: Routeadvies | K2: Grenswaarde | L2: Klasse | M2: Tot. nieuw CO2 (kg) | N2: Tot. hergebruik CO2 (kg) | O2: Tot. recycling Co2 (kg) | P2: Klimaatbespring kg Co2 | Q2: Routeadvies 2 | R2: Verkoopbare volume m³ | S2: Verkoopprijs per m³ | T2: Financiële marktwaarde excl. kosten | U2: Recovery hoog? | V2: Klimaat positief? | W2: Financiele positief? | X2: Eindbeoordeling
A3: Hout | B3: Totaal | C3: ='Hout-data'!B2 -> 1.35 | D3: 2 | E3: ="" | F3: =AVERAGE(F4:F12) -> 3.2222222 | G3: =AVERAGE(G4:G12) -> 3.1111111 | H3: =AVERAGE(H4:H12) -> 2.4444444 | I3: =IFERROR(ROUND(AVERAGE(Tabel26[[#This Row],[Demonteerbaarheid]],Tabel26[[#This Row],[Materiaalconditie ]],Tabel26[[#This Row],[Marktpotentie ]])/5,2),0) -> 0.59 | J3: =IF(I3="","Handmatig beoordelen",IF(I3>=0.8,"Hergebruik",IF(I3>=0.55,"Hergebruik > recycling",IF(I3>=0.3,"Recycling","Handmatig beoordelen")))) -> Hergebruik > recycling | K3: =IF(Tabel26[[#This Row],[Routeadvies]]="Hergebruik",">= 0,8",IF(Tabel26[[#This Row],[Routeadvies]]="Hergebruik > recycling",">= 0,55 en < 0,8",IF(Tabel26[[#This Row],[Routeadvies]]="Recycling",">= 0,3 en < 0,55",IF(Tabel26[[#This Row],[Routeadvies]]="Handmatig beoordelen","< 0,3 of geen score","")))) -> >= 0,55 en < 0,8 | L3: =IF($B3="Totaal","Totaal",IF($A3="Hout",IF(OR($B3="Trappen",$B3="Ramen",$B3="Deuren",$B3="Kozijnen",$B3="Dakkapellen",$B3="Dakconstructie"),"Bijzonder hout",IF($G3="","Handmatig beoordelen",IF($G3>=4,"A-hout",IF($G3>=3,"B-hout",IF($G3>0,"C-hout","Handmatig beoordelen"))))),IF($A3="Staal",IF(OR($B3="Kolommen",$B3="Balken",$B3="Liggers",$B3="Buisstaalconstructies",$B3="Kozijnen",$B3="Trappen",$B3="Hekwerken",$B3="Leuningen"),"Bijzonder staal",IF($G3="","Handmatig beoordelen",IF($G3>=4,"A-staal",IF($G3>=2,"B-staal",IF($G3>0,"C-staal","Handmatig beoordelen"))))),IF($A3="Beton",IF(OR($B3="Funderingen",$B3="Heipalen",$B3="Prefab elementen",$B3="Kanaalplaatvloeren",$B3="Breedplaatvloeren",$B3="Trappen",$B3="Gevelpanelen"),"Bijzonder beton",IF($G3="","Handmatig beoordelen",IF($G3>=4,"A-beton",IF($G3>=3,"B-beton",IF($G3>0,"C-beton","Handmatig beoordelen"))))),IF(OR($A3="Aluminium",$A3="Alumiunium"),IF(OR($B3="Ramen",$B3="Deuren",$B3="Kozijnen",$B3="Vliesgevels",$B3="Gevelsystemen",$B3="Zonwering",$B3="Trappen"),"Bijzonder aluminium",IF($G3="","Handmatig beoordelen",IF($G3>=4,"A-aluminium",IF($G3>=3,"B-aluminium",IF($G3>0,"C-aluminium","Handmatig beoordelen"))))),IF($A3="Koper",IF(OR($B3="Installaties",$B3="Technische ruimte",$B3="Verdeelkast",$B3="Meterkast",$B3="Bliksemafleiding",$B3="Leidingnetten"),"Bijzonder koper",IF($G3="","Handmatig beoordelen",IF($G3>=4,"A-koper",IF($G3>=3,"B-koper",IF($G3>0,"C-koper","Handmatig beoordelen"))))),IF($A3="Bitumen",IF(OR($B3="Dakopbouw",$B3="Groendak",$B3="Opstanden",$B3="Kimmen",$B3="Aansluitdetails",$B3="Dakdetails"),"Bijzonder bitumen",IF($G3="","Handmatig beoordelen",IF($G3>=4,"A-bitumen",IF($G3>=3,"B-bitumen",IF($G3>0,"C-bitumen","Handmatig beoordelen"))))),"Handmatig beoordelen"))))))) -> Totaal | M3: =SUM(M4:M12) -> 378 | N3: =SUM(N4:N12) -> 114.75 | O3: =SUM(O4:O12) -> 256.5 | P3: =IF(Q3="hergebruik",M3-N3,IF(Q3="recycling",O3-N3,"")) -> 263.25 | Q3: =IF(OR($M3="",$M3=0),"Geen beoordeling",IF(AND($N3=0,$O3=0),"Geen beoordeling",IF($N3<$O3,"Hergebruik",IF($O3<$N3,"Recycling","Hergebruik en recycling gelijk")))) -> Hergebruik | R3: =IFERROR(Tabel26[[#This Row],[BIM-volume m³]]*Tabel26[[#This Row],[PRR]],0) -> 0.7965 | S3: =IFERROR(VLOOKUP(Tabel26[[#This Row],[Klasse]],Hout!$A$11:$D$14,4,FALSE),0) -> 0 | T3: =R3*S3 -> 0 | U3: =IF(OR($L3="Handmatig beoordelen",$L3="",$L3="Totaal",$I3=""),"Handmatig",IF($I3>=70%,"Ja","Nee")) -> Handmatig | V3: =IF(OR($L3="Handmatig beoordelen",$L3="",$L3="Totaal"),"Handmatig",IF($P3>0,"Ja","Nee")) -> Handmatig | W3: =IF(OR($L3="Handmatig beoordelen",$L3="",$L3="Totaal"),"Handmatig",IF($T3>0,"Ja","Nee")) -> Handmatig | X3: =IF(OR($U3="Handmatig",$V3="Handmatig",$W3="Handmatig"),"Handmatig beoordelen",IF(COUNTIF($U3:$W3,"Ja")>=2,"Interessant",IF(COUNTIF($U3:$W3,"Ja")=1,"Eigen beoordeling","Niet interessant"))) -> Handmatig beoordelen
A4: Hout | B4: Plafonds | C4: ='Hout-data'!B3 -> 0 | D4: 2 | E4: 20 | F4: 1 | G4: 3 | H4: 2 | I4: =IFERROR(ROUND(AVERAGE(Tabel26[[#This Row],[Demonteerbaarheid]],Tabel26[[#This Row],[Materiaalconditie ]],Tabel26[[#This Row],[Marktpotentie ]])/5,2),0) -> 0.4 | J4: =IF(I4="","Handmatig beoordelen",IF(I4>=0.8,"Hergebruik",IF(I4>=0.55,"Hergebruik > recycling",IF(I4>=0.3,"Recycling","Handmatig beoordelen")))) -> Recycling | K4: =IF(Tabel26[[#This Row],[Routeadvies]]="Hergebruik",">= 0,8",IF(Tabel26[[#This Row],[Routeadvies]]="Hergebruik > recycling",">= 0,55 en < 0,8",IF(Tabel26[[#This Row],[Routeadvies]]="Recycling",">= 0,3 en < 0,55",IF(Tabel26[[#This Row],[Routeadvies]]="Handmatig beoordelen","< 0,3 of geen score","")))) -> >= 0,3 en < 0,55 | L4: =IF($B4="Totaal","Totaal",IF($A4="Hout",IF(OR($B4="Trappen",$B4="Ramen",$B4="Deuren",$B4="Kozijnen",$B4="Dakkapellen",$B4="Dakconstructie"),"Bijzonder hout",IF($G4="","Handmatig beoordelen",IF($G4>=4,"A-hout",IF($G4>=3,"B-hout",IF($G4>0,"C-hout","Handmatig beoordelen"))))),IF($A4="Staal",IF(OR($B4="Kolommen",$B4="Balken",$B4="Liggers",$B4="Buisstaalconstructies",$B4="Kozijnen",$B4="Trappen",$B4="Hekwerken",$B4="Leuningen"),"Bijzonder staal",IF($G4="","Handmatig beoordelen",IF($G4>=4,"A-staal",IF($G4>=2,"B-staal",IF($G4>0,"C-staal","Handmatig beoordelen"))))),IF($A4="Beton",IF(OR($B4="Funderingen",$B4="Heipalen",$B4="Prefab elementen",$B4="Kanaalplaatvloeren",$B4="Breedplaatvloeren",$B4="Trappen",$B4="Gevelpanelen"),"Bijzonder beton",IF($G4="","Handmatig beoordelen",IF($G4>=4,"A-beton",IF($G4>=3,"B-beton",IF($G4>0,"C-beton","Handmatig beoordelen"))))),IF(OR($A4="Aluminium",$A4="Alumiunium"),IF(OR($B4="Ramen",$B4="Deuren",$B4="Kozijnen",$B4="Vliesgevels",$B4="Gevelsystemen",$B4="Zonwering",$B4="Trappen"),"Bijzonder aluminium",IF($G4="","Handmatig beoordelen",IF($G4>=4,"A-aluminium",IF($G4>=3,"B-aluminium",IF($G4>0,"C-aluminium","Handmatig beoordelen"))))),IF($A4="Koper",IF(OR($B4="Installaties",$B4="Technische ruimte",$B4="Verdeelkast",$B4="Meterkast",$B4="Bliksemafleiding",$B4="Leidingnetten"),"Bijzonder koper",IF($G4="","Handmatig beoordelen",IF($G4>=4,"A-koper",IF($G4>=3,"B-koper",IF($G4>0,"C-koper","Handmatig beoordelen"))))),IF($A4="Bitumen",IF(OR($B4="Dakopbouw",$B4="Groendak",$B4="Opstanden",$B4="Kimmen",$B4="Aansluitdetails",$B4="Dakdetails"),"Bijzonder bitumen",IF($G4="","Handmatig beoordelen",IF($G4>=4,"A-bitumen",IF($G4>=3,"B-bitumen",IF($G4>0,"C-bitumen","Handmatig beoordelen"))))),"Handmatig beoordelen"))))))) -> B-hout | M4: =IFERROR(Tabel26[[#This Row],[BIM-volume m³]]*INDEX(Tabel113[CO2-nieuw (kg)],1)+Tabel26[[#This Row],[BIM-volume m³]]*INDEX(Tabel113[Transport-impact ],1)*IF(Tabel26[[#This Row],[Transportafstand (km)]]="",0,Tabel26[[#This Row],[Transportafstand (km)]]),0) -> 0 | N4: =IF(Tabel26[[#This Row],[Klasse]]="Totaal",SUM(M5:M12),IFERROR(Tabel26[[#This Row],[BIM-volume m³]]*INDEX(Tabel113[CO2-Hergebruik (kg)],1)+Tabel26[[#This Row],[BIM-volume m³]]*INDEX(Tabel113[Transport-impact ],1)*IF(Tabel26[[#This Row],[Transportafstand (km)]]="",0,Tabel26[[#This Row],[Transportafstand (km)]]),0)) -> 0 | O4: =IFERROR(Tabel26[[#This Row],[BIM-volume m³]]*INDEX(Tabel113[CO2- recycle (kg)],1)+Tabel26[[#This Row],[BIM-volume m³]]*Tabel26[[#This Row],[Transport Impact]]*IF(Tabel26[[#This Row],[Transportafstand (km)]]="",0,Tabel26[[#This Row],[Transportafstand (km)]]),0) -> 0 | P4: =IF($B11="Totaal",SUM($O$10),IFERROR(MAX(0,$M4-MIN($N4,$O4)),0)) -> 0 | Q4: =IF(OR($M4="",$M4=0),"Geen beoordeling",IF(AND($N4=0,$O4=0),"Geen beoordeling",IF($N4<$O4,"Hergebruik",IF($O4<$N4,"Recycling","Hergebruik en recycling gelijk")))) -> Geen beoordeling | R4: =IFERROR(Tabel26[[#This Row],[BIM-volume m³]]*Tabel26[[#This Row],[PRR]],0) -> 0 | S4: =IFERROR(VLOOKUP(Tabel26[[#This Row],[Klasse]],Hout!$A$11:$D$14,4,FALSE),0) -> 150 | T4: =R4*S4 -> 0 | U4: =IF(OR($L4="Handmatig beoordelen",$L4="",$L4="Totaal",$I4=""),"Handmatig",IF($I4>=70%,"Ja","Nee")) -> Nee | V4: =IF(OR($L4="Handmatig beoordelen",$L4="",$L4="Totaal"),"Handmatig",IF($P4>0,"Ja","Nee")) -> Nee | W4: =IF(OR($L4="Handmatig beoordelen",$L4="",$L4="Totaal"),"Handmatig",IF($T4>0,"Ja","Nee")) -> Nee | X4: =IF(OR($U4="Handmatig",$V4="Handmatig",$W4="Handmatig"),"Handmatig beoordelen",IF(COUNTIF($U4:$W4,"Ja")>=2,"Interessant",IF(COUNTIF($U4:$W4,"Ja")=1,"Eigen beoordeling","Niet interessant"))) -> Niet interessant
A5: Hout | B5: Kolommen | C5: ='Hout-data'!B4 -> 0 | D5: 2 | E5: 20 | F5: 1 | G5: 3 | H5: 3 | I5: =IFERROR(ROUND(AVERAGE(Tabel26[[#This Row],[Demonteerbaarheid]],Tabel26[[#This Row],[Materiaalconditie ]],Tabel26[[#This Row],[Marktpotentie ]])/5,2),0) -> 0.47 | J5: =IF(I5="","Handmatig beoordelen",IF(I5>=0.8,"Hergebruik",IF(I5>=0.55,"Hergebruik > recycling",IF(I5>=0.3,"Recycling","Handmatig beoordelen")))) -> Recycling | K5: =IF(Tabel26[[#This Row],[Routeadvies]]="Hergebruik",">= 0,8",IF(Tabel26[[#This Row],[Routeadvies]]="Hergebruik > recycling",">= 0,55 en < 0,8",IF(Tabel26[[#This Row],[Routeadvies]]="Recycling",">= 0,3 en < 0,55",IF(Tabel26[[#This Row],[Routeadvies]]="Handmatig beoordelen","< 0,3 of geen score","")))) -> >= 0,3 en < 0,55 | L5: =IF($B5="Totaal","Totaal",IF($A5="Hout",IF(OR($B5="Trappen",$B5="Ramen",$B5="Deuren",$B5="Kozijnen",$B5="Dakkapellen",$B5="Dakconstructie"),"Bijzonder hout",IF($G5="","Handmatig beoordelen",IF($G5>=4,"A-hout",IF($G5>=3,"B-hout",IF($G5>0,"C-hout","Handmatig beoordelen"))))),IF($A5="Staal",IF(OR($B5="Kolommen",$B5="Balken",$B5="Liggers",$B5="Buisstaalconstructies",$B5="Kozijnen",$B5="Trappen",$B5="Hekwerken",$B5="Leuningen"),"Bijzonder staal",IF($G5="","Handmatig beoordelen",IF($G5>=4,"A-staal",IF($G5>=2,"B-staal",IF($G5>0,"C-staal","Handmatig beoordelen"))))),IF($A5="Beton",IF(OR($B5="Funderingen",$B5="Heipalen",$B5="Prefab elementen",$B5="Kanaalplaatvloeren",$B5="Breedplaatvloeren",$B5="Trappen",$B5="Gevelpanelen"),"Bijzonder beton",IF($G5="","Handmatig beoordelen",IF($G5>=4,"A-beton",IF($G5>=3,"B-beton",IF($G5>0,"C-beton","Handmatig beoordelen"))))),IF(OR($A5="Aluminium",$A5="Alumiunium"),IF(OR($B5="Ramen",$B5="Deuren",$B5="Kozijnen",$B5="Vliesgevels",$B5="Gevelsystemen",$B5="Zonwering",$B5="Trappen"),"Bijzonder aluminium",IF($G5="","Handmatig beoordelen",IF($G5>=4,"A-aluminium",IF($G5>=3,"B-aluminium",IF($G5>0,"C-aluminium","Handmatig beoordelen"))))),IF($A5="Koper",IF(OR($B5="Installaties",$B5="Technische ruimte",$B5="Verdeelkast",$B5="Meterkast",$B5="Bliksemafleiding",$B5="Leidingnetten"),"Bijzonder koper",IF($G5="","Handmatig beoordelen",IF($G5>=4,"A-koper",IF($G5>=3,"B-koper",IF($G5>0,"C-koper","Handmatig beoordelen"))))),IF($A5="Bitumen",IF(OR($B5="Dakopbouw",$B5="Groendak",$B5="Opstanden",$B5="Kimmen",$B5="Aansluitdetails",$B5="Dakdetails"),"Bijzonder bitumen",IF($G5="","Handmatig beoordelen",IF($G5>=4,"A-bitumen",IF($G5>=3,"B-bitumen",IF($G5>0,"C-bitumen","Handmatig beoordelen"))))),"Handmatig beoordelen"))))))) -> B-hout | M5: =IFERROR(Tabel26[[#This Row],[BIM-volume m³]]*INDEX(Tabel113[CO2-nieuw (kg)],1)+Tabel26[[#This Row],[BIM-volume m³]]*INDEX(Tabel113[Transport-impact ],1)*IF(Tabel26[[#This Row],[Transportafstand (km)]]="",0,Tabel26[[#This Row],[Transportafstand (km)]]),0) -> 0 | N5: =IF(Tabel26[[#This Row],[Klasse]]="Totaal",SUM(M6:M14),IFERROR(Tabel26[[#This Row],[BIM-volume m³]]*INDEX(Tabel113[CO2-Hergebruik (kg)],1)+Tabel26[[#This Row],[BIM-volume m³]]*INDEX(Tabel113[Transport-impact ],1)*IF(Tabel26[[#This Row],[Transportafstand (km)]]="",0,Tabel26[[#This Row],[Transportafstand (km)]]),0)) -> 0 | O5: =IFERROR(Tabel26[[#This Row],[BIM-volume m³]]*INDEX(Tabel113[CO2- recycle (kg)],1)+Tabel26[[#This Row],[BIM-volume m³]]*Tabel26[[#This Row],[Transport Impact]]*IF(Tabel26[[#This Row],[Transportafstand (km)]]="",0,Tabel26[[#This Row],[Transportafstand (km)]]),0) -> 0 | P5: =IF($B12="Totaal",SUM($O$10),IFERROR(MAX(0,$M5-MIN($N5,$O5)),0)) -> 0 | Q5: =IF(OR($M5="",$M5=0),"Geen beoordeling",IF(AND($N5=0,$O5=0),"Geen beoordeling",IF($N5<$O5,"Hergebruik",IF($O5<$N5,"Recycling","Hergebruik en recycling gelijk")))) -> Geen beoordeling | R5: =IFERROR(Tabel26[[#This Row],[BIM-volume m³]]*Tabel26[[#This Row],[PRR]],0) -> 0 | S5: =IFERROR(VLOOKUP(Tabel26[[#This Row],[Klasse]],Hout!$A$11:$D$14,4,FALSE),0) -> 150 | T5: =R5*S5 -> 0 | U5: =IF(OR($L5="Handmatig beoordelen",$L5="",$L5="Totaal",$I5=""),"Handmatig",IF($I5>=70%,"Ja","Nee")) -> Nee | V5: =IF(OR($L5="Handmatig beoordelen",$L5="",$L5="Totaal"),"Handmatig",IF($P5>0,"Ja","Nee")) -> Nee | W5: =IF(OR($L5="Handmatig beoordelen",$L5="",$L5="Totaal"),"Handmatig",IF($T5>0,"Ja","Nee")) -> Nee | X5: =IF(OR($U5="Handmatig",$V5="Handmatig",$W5="Handmatig"),"Handmatig beoordelen",IF(COUNTIF($U5:$W5,"Ja")>=2,"Interessant",IF(COUNTIF($U5:$W5,"Ja")=1,"Eigen beoordeling","Niet interessant"))) -> Niet interessant
A6: Hout | B6: Gevelpanelen | C6: ='Hout-data'!B5 -> 0 | D6: 2 | E6: 20 | F6: 5 | G6: 4 | H6: 2 | I6: =IFERROR(ROUND(AVERAGE(Tabel26[[#This Row],[Demonteerbaarheid]],Tabel26[[#This Row],[Materiaalconditie ]],Tabel26[[#This Row],[Marktpotentie ]])/5,2),0) -> 0.73 | J6: =IF(I6="","Handmatig beoordelen",IF(I6>=0.8,"Hergebruik",IF(I6>=0.55,"Hergebruik > recycling",IF(I6>=0.3,"Recycling","Handmatig beoordelen")))) -> Hergebruik > recycling | K6: =IF(Tabel26[[#This Row],[Routeadvies]]="Hergebruik",">= 0,8",IF(Tabel26[[#This Row],[Routeadvies]]="Hergebruik > recycling",">= 0,55 en < 0,8",IF(Tabel26[[#This Row],[Routeadvies]]="Recycling",">= 0,3 en < 0,55",IF(Tabel26[[#This Row],[Routeadvies]]="Handmatig beoordelen","< 0,3 of geen score","")))) -> >= 0,55 en < 0,8 | L6: =IF($B6="Totaal","Totaal",IF($A6="Hout",IF(OR($B6="Trappen",$B6="Ramen",$B6="Deuren",$B6="Kozijnen",$B6="Dakkapellen",$B6="Dakconstructie"),"Bijzonder hout",IF($G6="","Handmatig beoordelen",IF($G6>=4,"A-hout",IF($G6>=3,"B-hout",IF($G6>0,"C-hout","Handmatig beoordelen"))))),IF($A6="Staal",IF(OR($B6="Kolommen",$B6="Balken",$B6="Liggers",$B6="Buisstaalconstructies",$B6="Kozijnen",$B6="Trappen",$B6="Hekwerken",$B6="Leuningen"),"Bijzonder staal",IF($G6="","Handmatig beoordelen",IF($G6>=4,"A-staal",IF($G6>=2,"B-staal",IF($G6>0,"C-staal","Handmatig beoordelen"))))),IF($A6="Beton",IF(OR($B6="Funderingen",$B6="Heipalen",$B6="Prefab elementen",$B6="Kanaalplaatvloeren",$B6="Breedplaatvloeren",$B6="Trappen",$B6="Gevelpanelen"),"Bijzonder beton",IF($G6="","Handmatig beoordelen",IF($G6>=4,"A-beton",IF($G6>=3,"B-beton",IF($G6>0,"C-beton","Handmatig beoordelen"))))),IF(OR($A6="Aluminium",$A6="Alumiunium"),IF(OR($B6="Ramen",$B6="Deuren",$B6="Kozijnen",$B6="Vliesgevels",$B6="Gevelsystemen",$B6="Zonwering",$B6="Trappen"),"Bijzonder aluminium",IF($G6="","Handmatig beoordelen",IF($G6>=4,"A-aluminium",IF($G6>=3,"B-aluminium",IF($G6>0,"C-aluminium","Handmatig beoordelen"))))),IF($A6="Koper",IF(OR($B6="Installaties",$B6="Technische ruimte",$B6="Verdeelkast",$B6="Meterkast",$B6="Bliksemafleiding",$B6="Leidingnetten"),"Bijzonder koper",IF($G6="","Handmatig beoordelen",IF($G6>=4,"A-koper",IF($G6>=3,"B-koper",IF($G6>0,"C-koper","Handmatig beoordelen"))))),IF($A6="Bitumen",IF(OR($B6="Dakopbouw",$B6="Groendak",$B6="Opstanden",$B6="Kimmen",$B6="Aansluitdetails",$B6="Dakdetails"),"Bijzonder bitumen",IF($G6="","Handmatig beoordelen",IF($G6>=4,"A-bitumen",IF($G6>=3,"B-bitumen",IF($G6>0,"C-bitumen","Handmatig beoordelen"))))),"Handmatig beoordelen"))))))) -> A-hout | M6: =IFERROR(Tabel26[[#This Row],[BIM-volume m³]]*INDEX(Tabel113[CO2-nieuw (kg)],1)+Tabel26[[#This Row],[BIM-volume m³]]*INDEX(Tabel113[Transport-impact ],1)*IF(Tabel26[[#This Row],[Transportafstand (km)]]="",0,Tabel26[[#This Row],[Transportafstand (km)]]),0) -> 0 | N6: =IF(Tabel26[[#This Row],[Klasse]]="Totaal",SUM(M7:M15),IFERROR(Tabel26[[#This Row],[BIM-volume m³]]*INDEX(Tabel113[CO2-Hergebruik (kg)],1)+Tabel26[[#This Row],[BIM-volume m³]]*INDEX(Tabel113[Transport-impact ],1)*IF(Tabel26[[#This Row],[Transportafstand (km)]]="",0,Tabel26[[#This Row],[Transportafstand (km)]]),0)) -> 0 | O6: =IFERROR(Tabel26[[#This Row],[BIM-volume m³]]*INDEX(Tabel113[CO2- recycle (kg)],1)+Tabel26[[#This Row],[BIM-volume m³]]*Tabel26[[#This Row],[Transport Impact]]*IF(Tabel26[[#This Row],[Transportafstand (km)]]="",0,Tabel26[[#This Row],[Transportafstand (km)]]),0) -> 0 | P6: =IF($B13="Totaal",SUM($O$10),IFERROR(MAX(0,$M6-MIN($N6,$O6)),0)) -> 0 | Q6: =IF(OR($M6="",$M6=0),"Geen beoordeling",IF(AND($N6=0,$O6=0),"Geen beoordeling",IF($N6<$O6,"Hergebruik",IF($O6<$N6,"Recycling","Hergebruik en recycling gelijk")))) -> Geen beoordeling | R6: =IFERROR(Tabel26[[#This Row],[BIM-volume m³]]*Tabel26[[#This Row],[PRR]],0) -> 0 | S6: =IFERROR(VLOOKUP(Tabel26[[#This Row],[Klasse]],Hout!$A$11:$D$14,4,FALSE),0) -> 243.75 | T6: =R6*S6 -> 0 | U6: =IF(OR($L6="Handmatig beoordelen",$L6="",$L6="Totaal",$I6=""),"Handmatig",IF($I6>=70%,"Ja","Nee")) -> Ja | V6: =IF(OR($L6="Handmatig beoordelen",$L6="",$L6="Totaal"),"Handmatig",IF($P6>0,"Ja","Nee")) -> Nee | W6: =IF(OR($L6="Handmatig beoordelen",$L6="",$L6="Totaal"),"Handmatig",IF($T6>0,"Ja","Nee")) -> Nee | X6: =IF(OR($U6="Handmatig",$V6="Handmatig",$W6="Handmatig"),"Handmatig beoordelen",IF(COUNTIF($U6:$W6,"Ja")>=2,"Interessant",IF(COUNTIF($U6:$W6,"Ja")=1,"Eigen beoordeling","Niet interessant"))) -> Eigen beoordeling
A7: Hout | B7: Deuren | C7: ='Hout-data'!B6 -> 0 | D7: 2 | E7: 20 | F7: 5 | G7: 3 | H7: 3 | I7: =IFERROR(ROUND(AVERAGE(Tabel26[[#This Row],[Demonteerbaarheid]],Tabel26[[#This Row],[Materiaalconditie ]],Tabel26[[#This Row],[Marktpotentie ]])/5,2),0) -> 0.73 | J7: =IF(I7="","Handmatig beoordelen",IF(I7>=0.8,"Hergebruik",IF(I7>=0.55,"Hergebruik > recycling",IF(I7>=0.3,"Recycling","Handmatig beoordelen")))) -> Hergebruik > recycling | K7: =IF(Tabel26[[#This Row],[Routeadvies]]="Hergebruik",">= 0,8",IF(Tabel26[[#This Row],[Routeadvies]]="Hergebruik > recycling",">= 0,55 en < 0,8",IF(Tabel26[[#This Row],[Routeadvies]]="Recycling",">= 0,3 en < 0,55",IF(Tabel26[[#This Row],[Routeadvies]]="Handmatig beoordelen","< 0,3 of geen score","")))) -> >= 0,55 en < 0,8 | L7: =IF($B7="Totaal","Totaal",IF($A7="Hout",IF(OR($B7="Trappen",$B7="Ramen",$B7="Deuren",$B7="Kozijnen",$B7="Dakkapellen",$B7="Dakconstructie"),"Bijzonder hout",IF($G7="","Handmatig beoordelen",IF($G7>=4,"A-hout",IF($G7>=3,"B-hout",IF($G7>0,"C-hout","Handmatig beoordelen"))))),IF($A7="Staal",IF(OR($B7="Kolommen",$B7="Balken",$B7="Liggers",$B7="Buisstaalconstructies",$B7="Kozijnen",$B7="Trappen",$B7="Hekwerken",$B7="Leuningen"),"Bijzonder staal",IF($G7="","Handmatig beoordelen",IF($G7>=4,"A-staal",IF($G7>=2,"B-staal",IF($G7>0,"C-staal","Handmatig beoordelen"))))),IF($A7="Beton",IF(OR($B7="Funderingen",$B7="Heipalen",$B7="Prefab elementen",$B7="Kanaalplaatvloeren",$B7="Breedplaatvloeren",$B7="Trappen",$B7="Gevelpanelen"),"Bijzonder beton",IF($G7="","Handmatig beoordelen",IF($G7>=4,"A-beton",IF($G7>=3,"B-beton",IF($G7>0,"C-beton","Handmatig beoordelen"))))),IF(OR($A7="Aluminium",$A7="Alumiunium"),IF(OR($B7="Ramen",$B7="Deuren",$B7="Kozijnen",$B7="Vliesgevels",$B7="Gevelsystemen",$B7="Zonwering",$B7="Trappen"),"Bijzonder aluminium",IF($G7="","Handmatig beoordelen",IF($G7>=4,"A-aluminium",IF($G7>=3,"B-aluminium",IF($G7>0,"C-aluminium","Handmatig beoordelen"))))),IF($A7="Koper",IF(OR($B7="Installaties",$B7="Technische ruimte",$B7="Verdeelkast",$B7="Meterkast",$B7="Bliksemafleiding",$B7="Leidingnetten"),"Bijzonder koper",IF($G7="","Handmatig beoordelen",IF($G7>=4,"A-koper",IF($G7>=3,"B-koper",IF($G7>0,"C-koper","Handmatig beoordelen"))))),IF($A7="Bitumen",IF(OR($B7="Dakopbouw",$B7="Groendak",$B7="Opstanden",$B7="Kimmen",$B7="Aansluitdetails",$B7="Dakdetails"),"Bijzonder bitumen",IF($G7="","Handmatig beoordelen",IF($G7>=4,"A-bitumen",IF($G7>=3,"B-bitumen",IF($G7>0,"C-bitumen","Handmatig beoordelen"))))),"Handmatig beoordelen"))))))) -> Bijzonder hout | M7: =IFERROR(Tabel26[[#This Row],[BIM-volume m³]]*INDEX(Tabel113[CO2-nieuw (kg)],1)+Tabel26[[#This Row],[BIM-volume m³]]*INDEX(Tabel113[Transport-impact ],1)*IF(Tabel26[[#This Row],[Transportafstand (km)]]="",0,Tabel26[[#This Row],[Transportafstand (km)]]),0) -> 0 | N7: =IF(Tabel26[[#This Row],[Klasse]]="Totaal",SUM(M8:M16),IFERROR(Tabel26[[#This Row],[BIM-volume m³]]*INDEX(Tabel113[CO2-Hergebruik (kg)],1)+Tabel26[[#This Row],[BIM-volume m³]]*INDEX(Tabel113[Transport-impact ],1)*IF(Tabel26[[#This Row],[Transportafstand (km)]]="",0,Tabel26[[#This Row],[Transportafstand (km)]]),0)) -> 0 | O7: =IFERROR(Tabel26[[#This Row],[BIM-volume m³]]*INDEX(Tabel113[CO2- recycle (kg)],1)+Tabel26[[#This Row],[BIM-volume m³]]*Tabel26[[#This Row],[Transport Impact]]*IF(Tabel26[[#This Row],[Transportafstand (km)]]="",0,Tabel26[[#This Row],[Transportafstand (km)]]),0) -> 0 | P7: =IF($B14="Totaal",SUM($O$10),IFERROR(MAX(0,$M7-MIN($N7,$O7)),0)) -> 0 | Q7: =IF(OR($M7="",$M7=0),"Geen beoordeling",IF(AND($N7=0,$O7=0),"Geen beoordeling",IF($N7<$O7,"Hergebruik",IF($O7<$N7,"Recycling","Hergebruik en recycling gelijk")))) -> Geen beoordeling | R7: =IFERROR(Tabel26[[#This Row],[BIM-volume m³]]*Tabel26[[#This Row],[PRR]],0) -> 0 | S7: =IFERROR(VLOOKUP(Tabel26[[#This Row],[Klasse]],Hout!$A$11:$D$14,4,FALSE),0) -> 900 | T7: =R7*S7 -> 0 | U7: =IF(OR($L7="Handmatig beoordelen",$L7="",$L7="Totaal",$I7=""),"Handmatig",IF($I7>=70%,"Ja","Nee")) -> Ja | V7: =IF(OR($L7="Handmatig beoordelen",$L7="",$L7="Totaal"),"Handmatig",IF($P7>0,"Ja","Nee")) -> Nee | W7: =IF(OR($L7="Handmatig beoordelen",$L7="",$L7="Totaal"),"Handmatig",IF($T7>0,"Ja","Nee")) -> Nee | X7: =IF(OR($U7="Handmatig",$V7="Handmatig",$W7="Handmatig"),"Handmatig beoordelen",IF(COUNTIF($U7:$W7,"Ja")>=2,"Interessant",IF(COUNTIF($U7:$W7,"Ja")=1,"Eigen beoordeling","Niet interessant"))) -> Eigen beoordeling
A8: Hout | B8: Vloeren | C8: ='Hout-data'!B7 -> 0.17 | D8: 2 | E8: 20 | F8: 1 | G8: 3 | H8: 2 | I8: =IFERROR(ROUND(AVERAGE(Tabel26[[#This Row],[Demonteerbaarheid]],Tabel26[[#This Row],[Materiaalconditie ]],Tabel26[[#This Row],[Marktpotentie ]])/5,2),0) -> 0.4 | J8: =IF(I8="","Handmatig beoordelen",IF(I8>=0.8,"Hergebruik",IF(I8>=0.55,"Hergebruik > recycling",IF(I8>=0.3,"Recycling","Handmatig beoordelen")))) -> Recycling | K8: =IF(Tabel26[[#This Row],[Routeadvies]]="Hergebruik",">= 0,8",IF(Tabel26[[#This Row],[Routeadvies]]="Hergebruik > recycling",">= 0,55 en < 0,8",IF(Tabel26[[#This Row],[Routeadvies]]="Recycling",">= 0,3 en < 0,55",IF(Tabel26[[#This Row],[Routeadvies]]="Handmatig beoordelen","< 0,3 of geen score","")))) -> >= 0,3 en < 0,55 | L8: =IF($B8="Totaal","Totaal",IF($A8="Hout",IF(OR($B8="Trappen",$B8="Ramen",$B8="Deuren",$B8="Kozijnen",$B8="Dakkapellen",$B8="Dakconstructie"),"Bijzonder hout",IF($G8="","Handmatig beoordelen",IF($G8>=4,"A-hout",IF($G8>=3,"B-hout",IF($G8>0,"C-hout","Handmatig beoordelen"))))),IF($A8="Staal",IF(OR($B8="Kolommen",$B8="Balken",$B8="Liggers",$B8="Buisstaalconstructies",$B8="Kozijnen",$B8="Trappen",$B8="Hekwerken",$B8="Leuningen"),"Bijzonder staal",IF($G8="","Handmatig beoordelen",IF($G8>=4,"A-staal",IF($G8>=2,"B-staal",IF($G8>0,"C-staal","Handmatig beoordelen"))))),IF($A8="Beton",IF(OR($B8="Funderingen",$B8="Heipalen",$B8="Prefab elementen",$B8="Kanaalplaatvloeren",$B8="Breedplaatvloeren",$B8="Trappen",$B8="Gevelpanelen"),"Bijzonder beton",IF($G8="","Handmatig beoordelen",IF($G8>=4,"A-beton",IF($G8>=3,"B-beton",IF($G8>0,"C-beton","Handmatig beoordelen"))))),IF(OR($A8="Aluminium",$A8="Alumiunium"),IF(OR($B8="Ramen",$B8="Deuren",$B8="Kozijnen",$B8="Vliesgevels",$B8="Gevelsystemen",$B8="Zonwering",$B8="Trappen"),"Bijzonder aluminium",IF($G8="","Handmatig beoordelen",IF($G8>=4,"A-aluminium",IF($G8>=3,"B-aluminium",IF($G8>0,"C-aluminium","Handmatig beoordelen"))))),IF($A8="Koper",IF(OR($B8="Installaties",$B8="Technische ruimte",$B8="Verdeelkast",$B8="Meterkast",$B8="Bliksemafleiding",$B8="Leidingnetten"),"Bijzonder koper",IF($G8="","Handmatig beoordelen",IF($G8>=4,"A-koper",IF($G8>=3,"B-koper",IF($G8>0,"C-koper","Handmatig beoordelen"))))),IF($A8="Bitumen",IF(OR($B8="Dakopbouw",$B8="Groendak",$B8="Opstanden",$B8="Kimmen",$B8="Aansluitdetails",$B8="Dakdetails"),"Bijzonder bitumen",IF($G8="","Handmatig beoordelen",IF($G8>=4,"A-bitumen",IF($G8>=3,"B-bitumen",IF($G8>0,"C-bitumen","Handmatig beoordelen"))))),"Handmatig beoordelen"))))))) -> B-hout | M8: =IFERROR(Tabel26[[#This Row],[BIM-volume m³]]*INDEX(Tabel113[CO2-nieuw (kg)],1)+Tabel26[[#This Row],[BIM-volume m³]]*Tabel26[[#This Row],[Transport Impact]]*IF(Tabel26[[#This Row],[Transportafstand (km)]]="",0,Tabel26[[#This Row],[Transportafstand (km)]]),0) -> 47.6 | N8: =IF(Tabel26[[#This Row],[Klasse]]="Totaal",SUM(M9:M17),IFERROR(Tabel26[[#This Row],[BIM-volume m³]]*INDEX(Tabel113[CO2-Hergebruik (kg)],1)+Tabel26[[#This Row],[BIM-volume m³]]*INDEX(Tabel113[Transport-impact ],1)*IF(Tabel26[[#This Row],[Transportafstand (km)]]="",0,Tabel26[[#This Row],[Transportafstand (km)]]),0)) -> 14.45 | O8: =IFERROR(Tabel26[[#This Row],[BIM-volume m³]]*INDEX(Tabel113[CO2- recycle (kg)],1)+Tabel26[[#This Row],[BIM-volume m³]]*Tabel26[[#This Row],[Transport Impact]]*IF(Tabel26[[#This Row],[Transportafstand (km)]]="",0,Tabel26[[#This Row],[Transportafstand (km)]]),0) -> 32.3 | P8: =IF(Q8="hergebruik",M8-N8,IF(Q8="recycling",O8-N8,"")) -> 33.15 | Q8: =IF(OR($M8="",$M8=0),"Geen beoordeling",IF(AND($N8=0,$O8=0),"Geen beoordeling",IF($N8<$O8,"Hergebruik",IF($O8<$N8,"Recycling","Hergebruik en recycling gelijk")))) -> Hergebruik | R8: =IFERROR(Tabel26[[#This Row],[BIM-volume m³]]*Tabel26[[#This Row],[PRR]],0) -> 0.068 | S8: =IFERROR(VLOOKUP(Tabel26[[#This Row],[Klasse]],Hout!$A$11:$D$14,4,FALSE),0) -> 150 | T8: =R8*S8 -> 10.2 | U8: =IF(OR($L8="Handmatig beoordelen",$L8="",$L8="Totaal",$I8=""),"Handmatig",IF($I8>=70%,"Ja","Nee")) -> Nee | V8: =IF(OR($L8="Handmatig beoordelen",$L8="",$L8="Totaal"),"Handmatig",IF($P8>0,"Ja","Nee")) -> Ja | W8: =IF(OR($L8="Handmatig beoordelen",$L8="",$L8="Totaal"),"Handmatig",IF($T8>0,"Ja","Nee")) -> Ja | X8: =IF(OR($U8="Handmatig",$V8="Handmatig",$W8="Handmatig"),"Handmatig beoordelen",IF(COUNTIF($U8:$W8,"Ja")>=2,"Interessant",IF(COUNTIF($U8:$W8,"Ja")=1,"Eigen beoordeling","Niet interessant"))) -> Interessant
A9: Hout | B9: Daken | C9: ='Hout-data'!B8 -> 0 | D9: 2 | E9: 20 | F9: 5 | G9: 3 | H9: 2 | I9: =IFERROR(ROUND(AVERAGE(Tabel26[[#This Row],[Demonteerbaarheid]],Tabel26[[#This Row],[Materiaalconditie ]],Tabel26[[#This Row],[Marktpotentie ]])/5,2),0) -> 0.67 | J9: =IF(I9="","Handmatig beoordelen",IF(I9>=0.8,"Hergebruik",IF(I9>=0.55,"Hergebruik > recycling",IF(I9>=0.3,"Recycling","Handmatig beoordelen")))) -> Hergebruik > recycling | K9: =IF(Tabel26[[#This Row],[Routeadvies]]="Hergebruik",">= 0,8",IF(Tabel26[[#This Row],[Routeadvies]]="Hergebruik > recycling",">= 0,55 en < 0,8",IF(Tabel26[[#This Row],[Routeadvies]]="Recycling",">= 0,3 en < 0,55",IF(Tabel26[[#This Row],[Routeadvies]]="Handmatig beoordelen","< 0,3 of geen score","")))) -> >= 0,55 en < 0,8 | L9: =IF($B9="Totaal","Totaal",IF($A9="Hout",IF(OR($B9="Trappen",$B9="Ramen",$B9="Deuren",$B9="Kozijnen",$B9="Dakkapellen",$B9="Dakconstructie"),"Bijzonder hout",IF($G9="","Handmatig beoordelen",IF($G9>=4,"A-hout",IF($G9>=3,"B-hout",IF($G9>0,"C-hout","Handmatig beoordelen"))))),IF($A9="Staal",IF(OR($B9="Kolommen",$B9="Balken",$B9="Liggers",$B9="Buisstaalconstructies",$B9="Kozijnen",$B9="Trappen",$B9="Hekwerken",$B9="Leuningen"),"Bijzonder staal",IF($G9="","Handmatig beoordelen",IF($G9>=4,"A-staal",IF($G9>=2,"B-staal",IF($G9>0,"C-staal","Handmatig beoordelen"))))),IF($A9="Beton",IF(OR($B9="Funderingen",$B9="Heipalen",$B9="Prefab elementen",$B9="Kanaalplaatvloeren",$B9="Breedplaatvloeren",$B9="Trappen",$B9="Gevelpanelen"),"Bijzonder beton",IF($G9="","Handmatig beoordelen",IF($G9>=4,"A-beton",IF($G9>=3,"B-beton",IF($G9>0,"C-beton","Handmatig beoordelen"))))),IF(OR($A9="Aluminium",$A9="Alumiunium"),IF(OR($B9="Ramen",$B9="Deuren",$B9="Kozijnen",$B9="Vliesgevels",$B9="Gevelsystemen",$B9="Zonwering",$B9="Trappen"),"Bijzonder aluminium",IF($G9="","Handmatig beoordelen",IF($G9>=4,"A-aluminium",IF($G9>=3,"B-aluminium",IF($G9>0,"C-aluminium","Handmatig beoordelen"))))),IF($A9="Koper",IF(OR($B9="Installaties",$B9="Technische ruimte",$B9="Verdeelkast",$B9="Meterkast",$B9="Bliksemafleiding",$B9="Leidingnetten"),"Bijzonder koper",IF($G9="","Handmatig beoordelen",IF($G9>=4,"A-koper",IF($G9>=3,"B-koper",IF($G9>0,"C-koper","Handmatig beoordelen"))))),IF($A9="Bitumen",IF(OR($B9="Dakopbouw",$B9="Groendak",$B9="Opstanden",$B9="Kimmen",$B9="Aansluitdetails",$B9="Dakdetails"),"Bijzonder bitumen",IF($G9="","Handmatig beoordelen",IF($G9>=4,"A-bitumen",IF($G9>=3,"B-bitumen",IF($G9>0,"C-bitumen","Handmatig beoordelen"))))),"Handmatig beoordelen"))))))) -> B-hout | M9: =IFERROR(Tabel26[[#This Row],[BIM-volume m³]]*INDEX(Tabel113[CO2-nieuw (kg)],1)+Tabel26[[#This Row],[BIM-volume m³]]*Tabel26[[#This Row],[Transport Impact]]*IF(Tabel26[[#This Row],[Transportafstand (km)]]="",0,Tabel26[[#This Row],[Transportafstand (km)]]),0) -> 0 | N9: =IF(Tabel26[[#This Row],[Klasse]]="Totaal",SUM(M10:M18),IFERROR(Tabel26[[#This Row],[BIM-volume m³]]*INDEX(Tabel113[CO2-Hergebruik (kg)],1)+Tabel26[[#This Row],[BIM-volume m³]]*INDEX(Tabel113[Transport-impact ],1)*IF(Tabel26[[#This Row],[Transportafstand (km)]]="",0,Tabel26[[#This Row],[Transportafstand (km)]]),0)) -> 0 | O9: =IFERROR(Tabel26[[#This Row],[BIM-volume m³]]*INDEX(Tabel113[CO2- recycle (kg)],1)+Tabel26[[#This Row],[BIM-volume m³]]*Tabel26[[#This Row],[Transport Impact]]*IF(Tabel26[[#This Row],[Transportafstand (km)]]="",0,Tabel26[[#This Row],[Transportafstand (km)]]),0) -> 0 | P9: =IF(Q9="hergebruik",M9-N9,IF(Q9="recycling",O9-N9,"")) | Q9: =IF(OR($M9="",$M9=0),"Geen beoordeling",IF(AND($N9=0,$O9=0),"Geen beoordeling",IF($N9<$O9,"Hergebruik",IF($O9<$N9,"Recycling","Hergebruik en recycling gelijk")))) -> Geen beoordeling | R9: =IFERROR(Tabel26[[#This Row],[BIM-volume m³]]*Tabel26[[#This Row],[PRR]],0) -> 0 | S9: =IFERROR(VLOOKUP(Tabel26[[#This Row],[Klasse]],Hout!$A$11:$D$14,4,FALSE),0) -> 150 | T9: =R9*S9 -> 0 | U9: =IF(OR($L9="Handmatig beoordelen",$L9="",$L9="Totaal",$I9=""),"Handmatig",IF($I9>=70%,"Ja","Nee")) -> Nee | V9: =IF(OR($L9="Handmatig beoordelen",$L9="",$L9="Totaal"),"Handmatig",IF($P9>0,"Ja","Nee")) -> Ja | W9: =IF(OR($L9="Handmatig beoordelen",$L9="",$L9="Totaal"),"Handmatig",IF($T9>0,"Ja","Nee")) -> Nee | X9: =IF(OR($U9="Handmatig",$V9="Handmatig",$W9="Handmatig"),"Handmatig beoordelen",IF(COUNTIF($U9:$W9,"Ja")>=2,"Interessant",IF(COUNTIF($U9:$W9,"Ja")=1,"Eigen beoordeling","Niet interessant"))) -> Eigen beoordeling
A10: Hout | B10: Wanden | C10: ='Hout-data'!B9 -> 1.18 | D10: 2 | E10: 20 | F10: 1 | G10: 3 | H10: 2 | I10: =IFERROR(ROUND(AVERAGE(Tabel26[[#This Row],[Demonteerbaarheid]],Tabel26[[#This Row],[Materiaalconditie ]],Tabel26[[#This Row],[Marktpotentie ]])/5,2),0) -> 0.4 | J10: =IF(I10="","Handmatig beoordelen",IF(I10>=0.8,"Hergebruik",IF(I10>=0.55,"Hergebruik > recycling",IF(I10>=0.3,"Recycling","Handmatig beoordelen")))) -> Recycling | K10: =IF(Tabel26[[#This Row],[Routeadvies]]="Hergebruik",">= 0,8",IF(Tabel26[[#This Row],[Routeadvies]]="Hergebruik > recycling",">= 0,55 en < 0,8",IF(Tabel26[[#This Row],[Routeadvies]]="Recycling",">= 0,3 en < 0,55",IF(Tabel26[[#This Row],[Routeadvies]]="Handmatig beoordelen","< 0,3 of geen score","")))) -> >= 0,3 en < 0,55 | L10: =IF($B10="Totaal","Totaal",IF($A10="Hout",IF(OR($B10="Trappen",$B10="Ramen",$B10="Deuren",$B10="Kozijnen",$B10="Dakkapellen",$B10="Dakconstructie"),"Bijzonder hout",IF($G10="","Handmatig beoordelen",IF($G10>=4,"A-hout",IF($G10>=3,"B-hout",IF($G10>0,"C-hout","Handmatig beoordelen"))))),IF($A10="Staal",IF(OR($B10="Kolommen",$B10="Balken",$B10="Liggers",$B10="Buisstaalconstructies",$B10="Kozijnen",$B10="Trappen",$B10="Hekwerken",$B10="Leuningen"),"Bijzonder staal",IF($G10="","Handmatig beoordelen",IF($G10>=4,"A-staal",IF($G10>=2,"B-staal",IF($G10>0,"C-staal","Handmatig beoordelen"))))),IF($A10="Beton",IF(OR($B10="Funderingen",$B10="Heipalen",$B10="Prefab elementen",$B10="Kanaalplaatvloeren",$B10="Breedplaatvloeren",$B10="Trappen",$B10="Gevelpanelen"),"Bijzonder beton",IF($G10="","Handmatig beoordelen",IF($G10>=4,"A-beton",IF($G10>=3,"B-beton",IF($G10>0,"C-beton","Handmatig beoordelen"))))),IF(OR($A10="Aluminium",$A10="Alumiunium"),IF(OR($B10="Ramen",$B10="Deuren",$B10="Kozijnen",$B10="Vliesgevels",$B10="Gevelsystemen",$B10="Zonwering",$B10="Trappen"),"Bijzonder aluminium",IF($G10="","Handmatig beoordelen",IF($G10>=4,"A-aluminium",IF($G10>=3,"B-aluminium",IF($G10>0,"C-aluminium","Handmatig beoordelen"))))),IF($A10="Koper",IF(OR($B10="Installaties",$B10="Technische ruimte",$B10="Verdeelkast",$B10="Meterkast",$B10="Bliksemafleiding",$B10="Leidingnetten"),"Bijzonder koper",IF($G10="","Handmatig beoordelen",IF($G10>=4,"A-koper",IF($G10>=3,"B-koper",IF($G10>0,"C-koper","Handmatig beoordelen"))))),IF($A10="Bitumen",IF(OR($B10="Dakopbouw",$B10="Groendak",$B10="Opstanden",$B10="Kimmen",$B10="Aansluitdetails",$B10="Dakdetails"),"Bijzonder bitumen",IF($G10="","Handmatig beoordelen",IF($G10>=4,"A-bitumen",IF($G10>=3,"B-bitumen",IF($G10>0,"C-bitumen","Handmatig beoordelen"))))),"Handmatig beoordelen"))))))) -> B-hout | M10: =IFERROR(Tabel26[[#This Row],[BIM-volume m³]]*INDEX(Tabel113[CO2-nieuw (kg)],1)+Tabel26[[#This Row],[BIM-volume m³]]*Tabel26[[#This Row],[Transport Impact]]*IF(Tabel26[[#This Row],[Transportafstand (km)]]="",0,Tabel26[[#This Row],[Transportafstand (km)]]),0) -> 330.4 | N10: =IF(Tabel26[[#This Row],[Klasse]]="Totaal",SUM(M11:M19),IFERROR(Tabel26[[#This Row],[BIM-volume m³]]*INDEX(Tabel113[CO2-Hergebruik (kg)],1)+Tabel26[[#This Row],[BIM-volume m³]]*INDEX(Tabel113[Transport-impact ],1)*IF(Tabel26[[#This Row],[Transportafstand (km)]]="",0,Tabel26[[#This Row],[Transportafstand (km)]]),0)) -> 100.3 | O10: =IFERROR(Tabel26[[#This Row],[BIM-volume m³]]*INDEX(Tabel113[CO2- recycle (kg)],1)+Tabel26[[#This Row],[BIM-volume m³]]*Tabel26[[#This Row],[Transport Impact]]*IF(Tabel26[[#This Row],[Transportafstand (km)]]="",0,Tabel26[[#This Row],[Transportafstand (km)]]),0) -> 224.2 | P10: =IF(Q10="hergebruik",M10-N10,IF(Q10="recycling",O10-N10,"")) -> 230.1 | Q10: =IF(OR($M10="",$M10=0),"Geen beoordeling",IF(AND($N10=0,$O10=0),"Geen beoordeling",IF($N10<$O10,"Hergebruik",IF($O10<$N10,"Recycling","Hergebruik en recycling gelijk")))) -> Hergebruik | R10: =IFERROR(Tabel26[[#This Row],[BIM-volume m³]]*Tabel26[[#This Row],[PRR]],0) -> 0.472 | S10: =IFERROR(VLOOKUP(Tabel26[[#This Row],[Klasse]],Hout!$A$11:$D$14,4,FALSE),0) -> 150 | T10: =R10*S10 -> 70.8 | U10: =IF(OR($L10="Handmatig beoordelen",$L10="",$L10="Totaal",$I10=""),"Handmatig",IF($I10>=70%,"Ja","Nee")) -> Nee | V10: =IF(OR($L10="Handmatig beoordelen",$L10="",$L10="Totaal"),"Handmatig",IF($P10>0,"Ja","Nee")) -> Ja | W10: =IF(OR($L10="Handmatig beoordelen",$L10="",$L10="Totaal"),"Handmatig",IF($T10>0,"Ja","Nee")) -> Ja | X10: =IF(OR($U10="Handmatig",$V10="Handmatig",$W10="Handmatig"),"Handmatig beoordelen",IF(COUNTIF($U10:$W10,"Ja")>=2,"Interessant",IF(COUNTIF($U10:$W10,"Ja")=1,"Eigen beoordeling","Niet interessant"))) -> Interessant
A11: Hout | B11: Ramen | C11: ='Hout-data'!B10 -> 0 | D11: 2 | E11: 20 | F11: 5 | G11: 2 | H11: 1 | I11: =IFERROR(ROUND(AVERAGE(Tabel26[[#This Row],[Demonteerbaarheid]],Tabel26[[#This Row],[Materiaalconditie ]],Tabel26[[#This Row],[Marktpotentie ]])/5,2),0) -> 0.53 | J11: =IF(I11="","Handmatig beoordelen",IF(I11>=0.8,"Hergebruik",IF(I11>=0.55,"Hergebruik > recycling",IF(I11>=0.3,"Recycling","Handmatig beoordelen")))) -> Recycling | K11: =IF(Tabel26[[#This Row],[Routeadvies]]="Hergebruik",">= 0,8",IF(Tabel26[[#This Row],[Routeadvies]]="Hergebruik > recycling",">= 0,55 en < 0,8",IF(Tabel26[[#This Row],[Routeadvies]]="Recycling",">= 0,3 en < 0,55",IF(Tabel26[[#This Row],[Routeadvies]]="Handmatig beoordelen","< 0,3 of geen score","")))) -> >= 0,3 en < 0,55 | L11: =IF($B11="Totaal","Totaal",IF($A11="Hout",IF(OR($B11="Trappen",$B11="Ramen",$B11="Deuren",$B11="Kozijnen",$B11="Dakkapellen",$B11="Dakconstructie"),"Bijzonder hout",IF($G11="","Handmatig beoordelen",IF($G11>=4,"A-hout",IF($G11>=3,"B-hout",IF($G11>0,"C-hout","Handmatig beoordelen"))))),IF($A11="Staal",IF(OR($B11="Kolommen",$B11="Balken",$B11="Liggers",$B11="Buisstaalconstructies",$B11="Kozijnen",$B11="Trappen",$B11="Hekwerken",$B11="Leuningen"),"Bijzonder staal",IF($G11="","Handmatig beoordelen",IF($G11>=4,"A-staal",IF($G11>=2,"B-staal",IF($G11>0,"C-staal","Handmatig beoordelen"))))),IF($A11="Beton",IF(OR($B11="Funderingen",$B11="Heipalen",$B11="Prefab elementen",$B11="Kanaalplaatvloeren",$B11="Breedplaatvloeren",$B11="Trappen",$B11="Gevelpanelen"),"Bijzonder beton",IF($G11="","Handmatig beoordelen",IF($G11>=4,"A-beton",IF($G11>=3,"B-beton",IF($G11>0,"C-beton","Handmatig beoordelen"))))),IF(OR($A11="Aluminium",$A11="Alumiunium"),IF(OR($B11="Ramen",$B11="Deuren",$B11="Kozijnen",$B11="Vliesgevels",$B11="Gevelsystemen",$B11="Zonwering",$B11="Trappen"),"Bijzonder aluminium",IF($G11="","Handmatig beoordelen",IF($G11>=4,"A-aluminium",IF($G11>=3,"B-aluminium",IF($G11>0,"C-aluminium","Handmatig beoordelen"))))),IF($A11="Koper",IF(OR($B11="Installaties",$B11="Technische ruimte",$B11="Verdeelkast",$B11="Meterkast",$B11="Bliksemafleiding",$B11="Leidingnetten"),"Bijzonder koper",IF($G11="","Handmatig beoordelen",IF($G11>=4,"A-koper",IF($G11>=3,"B-koper",IF($G11>0,"C-koper","Handmatig beoordelen"))))),IF($A11="Bitumen",IF(OR($B11="Dakopbouw",$B11="Groendak",$B11="Opstanden",$B11="Kimmen",$B11="Aansluitdetails",$B11="Dakdetails"),"Bijzonder bitumen",IF($G11="","Handmatig beoordelen",IF($G11>=4,"A-bitumen",IF($G11>=3,"B-bitumen",IF($G11>0,"C-bitumen","Handmatig beoordelen"))))),"Handmatig beoordelen"))))))) -> Bijzonder hout | M11: =IFERROR(Tabel26[[#This Row],[BIM-volume m³]]*INDEX(Tabel113[CO2-nieuw (kg)],1)+Tabel26[[#This Row],[BIM-volume m³]]*Tabel26[[#This Row],[Transport Impact]]*IF(Tabel26[[#This Row],[Transportafstand (km)]]="",0,Tabel26[[#This Row],[Transportafstand (km)]]),0) -> 0 | N11: =IF(Tabel26[[#This Row],[Klasse]]="Totaal",SUM(M12:M20),IFERROR(Tabel26[[#This Row],[BIM-volume m³]]*INDEX(Tabel113[CO2-Hergebruik (kg)],1)+Tabel26[[#This Row],[BIM-volume m³]]*INDEX(Tabel113[Transport-impact ],1)*IF(Tabel26[[#This Row],[Transportafstand (km)]]="",0,Tabel26[[#This Row],[Transportafstand (km)]]),0)) -> 0 | O11: =IFERROR(Tabel26[[#This Row],[BIM-volume m³]]*INDEX(Tabel113[CO2- recycle (kg)],1)+Tabel26[[#This Row],[BIM-volume m³]]*Tabel26[[#This Row],[Transport Impact]]*IF(Tabel26[[#This Row],[Transportafstand (km)]]="",0,Tabel26[[#This Row],[Transportafstand (km)]]),0) -> 0 | P11: =IF(Q11="hergebruik",M11-N11,IF(Q11="recycling",O11-N11,"")) | Q11: =IF(OR($M11="",$M11=0),"Geen beoordeling",IF(AND($N11=0,$O11=0),"Geen beoordeling",IF($N11<$O11,"Hergebruik",IF($O11<$N11,"Recycling","Hergebruik en recycling gelijk")))) -> Geen beoordeling | R11: =IFERROR(Tabel26[[#This Row],[BIM-volume m³]]*Tabel26[[#This Row],[PRR]],0) -> 0 | S11: =IFERROR(VLOOKUP(Tabel26[[#This Row],[Klasse]],Hout!$A$11:$D$14,4,FALSE),0) -> 900 | T11: =R11*S11 -> 0 | U11: =IF(OR($L11="Handmatig beoordelen",$L11="",$L11="Totaal",$I11=""),"Handmatig",IF($I11>=70%,"Ja","Nee")) -> Nee | V11: =IF(OR($L11="Handmatig beoordelen",$L11="",$L11="Totaal"),"Handmatig",IF($P11>0,"Ja","Nee")) -> Ja | W11: =IF(OR($L11="Handmatig beoordelen",$L11="",$L11="Totaal"),"Handmatig",IF($T11>0,"Ja","Nee")) -> Nee | X11: =IF(OR($U11="Handmatig",$V11="Handmatig",$W11="Handmatig"),"Handmatig beoordelen",IF(COUNTIF($U11:$W11,"Ja")>=2,"Interessant",IF(COUNTIF($U11:$W11,"Ja")=1,"Eigen beoordeling","Niet interessant"))) -> Eigen beoordeling
A12: Hout | B12: Trappen | C12: ='Hout-data'!B11 -> 0 | D12: 2 | E12: 20 | F12: 5 | G12: 4 | H12: 5 | I12: =IFERROR(ROUND(AVERAGE(F12,G12,H12)/5,2),0) -> 0.93 | J12: =IF(I12="","Handmatig beoordelen",IF(I12>=0.8,"Hergebruik",IF(I12>=0.55,"Hergebruik > recycling",IF(I12>=0.3,"Recycling","Handmatig beoordelen")))) -> Hergebruik | K12: =IF(Tabel26[[#This Row],[Routeadvies]]="Hergebruik",">= 0,8",IF(Tabel26[[#This Row],[Routeadvies]]="Hergebruik > recycling",">= 0,55 en < 0,8",IF(Tabel26[[#This Row],[Routeadvies]]="Recycling",">= 0,3 en < 0,55",IF(Tabel26[[#This Row],[Routeadvies]]="Handmatig beoordelen","< 0,3 of geen score","")))) -> >= 0,8 | L12: =IF($B12="Totaal","Totaal",IF($A12="Hout",IF(OR($B12="Trappen",$B12="Ramen",$B12="Deuren",$B12="Kozijnen",$B12="Dakkapellen",$B12="Dakconstructie"),"Bijzonder hout",IF($G12="","Handmatig beoordelen",IF($G12>=4,"A-hout",IF($G12>=3,"B-hout",IF($G12>0,"C-hout","Handmatig beoordelen"))))),IF($A12="Staal",IF(OR($B12="Kolommen",$B12="Balken",$B12="Liggers",$B12="Buisstaalconstructies",$B12="Kozijnen",$B12="Trappen",$B12="Hekwerken",$B12="Leuningen"),"Bijzonder staal",IF($G12="","Handmatig beoordelen",IF($G12>=4,"A-staal",IF($G12>=2,"B-staal",IF($G12>0,"C-staal","Handmatig beoordelen"))))),IF($A12="Beton",IF(OR($B12="Funderingen",$B12="Heipalen",$B12="Prefab elementen",$B12="Kanaalplaatvloeren",$B12="Breedplaatvloeren",$B12="Trappen",$B12="Gevelpanelen"),"Bijzonder beton",IF($G12="","Handmatig beoordelen",IF($G12>=4,"A-beton",IF($G12>=3,"B-beton",IF($G12>0,"C-beton","Handmatig beoordelen"))))),IF(OR($A12="Aluminium",$A12="Alumiunium"),IF(OR($B12="Ramen",$B12="Deuren",$B12="Kozijnen",$B12="Vliesgevels",$B12="Gevelsystemen",$B12="Zonwering",$B12="Trappen"),"Bijzonder aluminium",IF($G12="","Handmatig beoordelen",IF($G12>=4,"A-aluminium",IF($G12>=3,"B-aluminium",IF($G12>0,"C-aluminium","Handmatig beoordelen"))))),IF($A12="Koper",IF(OR($B12="Installaties",$B12="Technische ruimte",$B12="Verdeelkast",$B12="Meterkast",$B12="Bliksemafleiding",$B12="Leidingnetten"),"Bijzonder koper",IF($G12="","Handmatig beoordelen",IF($G12>=4,"A-koper",IF($G12>=3,"B-koper",IF($G12>0,"C-koper","Handmatig beoordelen"))))),IF($A12="Bitumen",IF(OR($B12="Dakopbouw",$B12="Groendak",$B12="Opstanden",$B12="Kimmen",$B12="Aansluitdetails",$B12="Dakdetails"),"Bijzonder bitumen",IF($G12="","Handmatig beoordelen",IF($G12>=4,"A-bitumen",IF($G12>=3,"B-bitumen",IF($G12>0,"C-bitumen","Handmatig beoordelen"))))),"Handmatig beoordelen"))))))) -> Bijzonder hout | M12: =IFERROR(Tabel26[[#This Row],[BIM-volume m³]]*INDEX(Tabel113[CO2-nieuw (kg)],1)+Tabel26[[#This Row],[BIM-volume m³]]*Tabel26[[#This Row],[Transport Impact]]*IF(Tabel26[[#This Row],[Transportafstand (km)]]="",0,Tabel26[[#This Row],[Transportafstand (km)]]),0) -> 0 | O12: =IFERROR(Tabel26[[#This Row],[BIM-volume m³]]*INDEX(Tabel113[CO2- recycle (kg)],1)+Tabel26[[#This Row],[BIM-volume m³]]*Tabel26[[#This Row],[Transport Impact]]*IF(Tabel26[[#This Row],[Transportafstand (km)]]="",0,Tabel26[[#This Row],[Transportafstand (km)]]),0) -> 0 | P12: =IF($B19="Totaal",SUM($O$4:$O$12),IFERROR(MAX(0,$M12-MIN($N12,$O12)),0)) -> 0 | Q12: =IF(OR($M12="",$M12=0),"Geen beoordeling",IF(AND($N12=0,$O12=0),"Geen beoordeling",IF($N12<$O12,"Hergebruik",IF($O12<$N12,"Recycling","Hergebruik en recycling gelijk")))) -> Geen beoordeling | R12: =IFERROR(Tabel26[[#This Row],[BIM-volume m³]]*Tabel26[[#This Row],[PRR]],0) -> 0 | S12: =IFERROR(VLOOKUP(Tabel26[[#This Row],[Klasse]],Hout!$A$11:$D$14,4,FALSE),0) -> 900 | T12: =R12*S12 -> 0 | U12: =IF(OR($L12="Handmatig beoordelen",$L12="",$L12="Totaal",$I12=""),"Handmatig",IF($I12>=70%,"Ja","Nee")) -> Ja | V12: =IF(OR($L12="Handmatig beoordelen",$L12="",$L12="Totaal"),"Handmatig",IF($P12>0,"Ja","Nee")) -> Nee | W12: =IF(OR($L12="Handmatig beoordelen",$L12="",$L12="Totaal"),"Handmatig",IF($T12>0,"Ja","Nee")) -> Nee | X12: =IF(OR($U12="Handmatig",$V12="Handmatig",$W12="Handmatig"),"Handmatig beoordelen",IF(COUNTIF($U12:$W12,"Ja")>=2,"Interessant",IF(COUNTIF($U12:$W12,"Ja")=1,"Eigen beoordeling","Niet interessant"))) -> Eigen beoordeling
A14: Materiaalstroom | B14: Bouwdeel uit BIM | C14: BIM-volume m³ | D14: Transport Impact | E14: Transportafstand (km) | F14: Demonteerbaarheid | G14: Materiaalconditie | H14: Marktpotentie | I14: PRR | J14: Routeadvies | K14: Grenswaarde | L14: Klasse | M14: Tot. nieuw CO2 (kg) | N14: Tot. hergebruik CO2 (kg) | O14: Tot. recycling Co2 (kg) | P14: Klimaatbesparing kg CO₂ | Q14: Routeadvies 2 | R14: Praktisch terugwinbaar volume m³ | S14: Verkoopprijs per m³ | T14: Financiële marktwaarde excl. kosten | U14: Recovery hoog? | V14: Klimaat positief? | W14: Financiele positief? | X14: Eindbeoordeling
A15: Staal | B15: Totaal | C15: ='Staal-data'!B2 -> 0 | D15: 4 | E15: ="" | F15: =AVERAGE(F16:F24) -> 3.2222222 | G15: =AVERAGE(G16:G24) -> 2.8888889 | H15: =AVERAGE(H16:H24) -> 3.4444444 | I15: =IFERROR(ROUND(AVERAGE(Tabel2640[[#This Row],[Demonteerbaarheid]],Tabel2640[[#This Row],[Materiaalconditie ]],Tabel2640[[#This Row],[Marktpotentie ]])/5,2),0) -> 0.64 | J15: =IF(Tabel2640[[#This Row],[PRR]]="","Handmatig beoordelen",IF(Tabel2640[[#This Row],[PRR]]>=0.75,"Hergebruik",IF(Tabel2640[[#This Row],[PRR]]>=0.4,"Hergebruik > recycling",IF(Tabel2640[[#This Row],[PRR]]>=0.15,"Recycling","Handmatig beoordelen")))) -> Hergebruik > recycling | K15: =IF(Tabel2640[[#This Row],[Routeadvies]]="Hergebruik",">= 0,75",IF(Tabel2640[[#This Row],[Routeadvies]]="Hergebruik > recycling",">= 0,4 en < 0,75",IF(Tabel2640[[#This Row],[Routeadvies]]="Recycling",">= 0,15 en < 0,4",IF(Tabel2640[[#This Row],[Routeadvies]]="Handmatig beoordelen","< 0,15 of geen score","")))) -> >= 0,4 en < 0,75 | L15: =IF($B15="Totaal","Totaal",IF(OR($B15="deuren",$B15="Balken",$B15="Liggers",$B15="Buisstaalconstructies",$B15="Kozijnen",$B15="Trappen",$B15="Hekwerken",$B15="Leuningen",$B15="ramen"),"Bijzonder staal",IF($G15="","Handmatig beoordelen",IF($G15>=4,"A-staal",IF($G15>=2,"B-staal",IF($G15>0,"C-staal","Handmatig beoordelen")))))) -> Totaal | M15: =IFERROR(Tabel2640[[#This Row],[BIM-volume m³]]*INDEX(Tabel17[CO2-nieuw (kg)],1)+Tabel2640[[#This Row],[BIM-volume m³]]*Tabel2640[[#This Row],[Transport Impact]]*IF(Tabel2640[[#This Row],[Transportafstand (km)]]="",0,Tabel2640[[#This Row],[Transportafstand (km)]]),0) -> 0 | N15: =SUM(N16:N24) -> 0 | O15: =SUM(O16:O24) -> 0 | P15: =IF($B10="Totaal",SUM($P$16:$P$24),IFERROR(MAX(0,$M14-MIN($N15,$O15)),0)) -> 0 | Q15: =IF(OR($M14="",$M14=0),"Geen beoordeling",IF(AND($N15=0,$O15=0),"Geen beoordeling",IF($N15<$O15,"Hergebruik",IF($O15<$N15,"Recycling","Hergebruik en recycling gelijk")))) -> Geen beoordeling | R15: =IFERROR(Tabel2640[[#This Row],[BIM-volume m³]]*Tabel2640[[#This Row],[PRR]],0) -> 0 | S15: =IFERROR(VLOOKUP(Tabel2640[[#This Row],[Klasse]],Staal!$A$10:$D$13,4,FALSE),0) -> 0 | T15: =Tabel2640[[#This Row],[Praktisch terugwinbaar volume m³]]*Tabel2640[[#This Row],[Verkoopprijs per m³]] -> 0 | U15: =IF(OR($L15="Handmatig beoordelen",$L15="",$L15="Totaal",$I15=""),"Handmatig",IF($I15>=70%,"Ja","Nee")) -> Handmatig | V15: =IF(OR($L15="Handmatig beoordelen",$L15="",$L15="Totaal",$Q15=""),"Handmatig",IF(OR($Q15="Hergebruik",$Q15="Recycling",$Q15="Hergebruik en recycling",$Q15="Hergebruik en recycling gelijk"),"Ja","Nee")) -> Handmatig | W15: =IF(OR($L15="Handmatig beoordelen",$L15="",$L15="Totaal"),"Handmatig",IF($T15>0,"Ja","Nee")) -> Handmatig | X15: =IF(OR($U15="Handmatig",$V15="Handmatig",$W15="Handmatig"),"Handmatig beoordelen",IF(COUNTIF($U15:$W15,"Ja")>=2,"Interessant",IF(COUNTIF($U15:$W15,"Ja")=1,"Eigen beoordeling","Niet interessant"))) -> Handmatig beoordelen
A16: Staal | B16: Plafonds | C16: ='Staal-data'!B3 -> 0 | D16: 4 | E16: 20 | F16: 1 | G16: 3 | H16: 4 | I16: =IFERROR(ROUND(AVERAGE(Tabel2640[[#This Row],[Demonteerbaarheid]],Tabel2640[[#This Row],[Materiaalconditie ]],Tabel2640[[#This Row],[Marktpotentie ]])/5,2),0) -> 0.53 | J16: =IF(Tabel2640[[#This Row],[PRR]]="","Handmatig beoordelen",IF(Tabel2640[[#This Row],[PRR]]>=0.75,"Hergebruik",IF(Tabel2640[[#This Row],[PRR]]>=0.4,"Hergebruik > recycling",IF(Tabel2640[[#This Row],[PRR]]>=0.15,"Recycling","Handmatig beoordelen")))) -> Hergebruik > recycling | K16: =IF(Tabel2640[[#This Row],[Routeadvies]]="Hergebruik",">= 0,75",IF(Tabel2640[[#This Row],[Routeadvies]]="Hergebruik > recycling",">= 0,4 en < 0,75",IF(Tabel2640[[#This Row],[Routeadvies]]="Recycling",">= 0,15 en < 0,4",IF(Tabel2640[[#This Row],[Routeadvies]]="Handmatig beoordelen","< 0,15 of geen score","")))) -> >= 0,4 en < 0,75 | L16: =IF($B16="Totaal","Totaal",IF(OR($B16="deuren",$B16="Balken",$B16="Liggers",$B16="Buisstaalconstructies",$B16="Kozijnen",$B16="Trappen",$B16="Hekwerken",$B16="Leuningen",$B16="ramen"),"Bijzonder staal",IF($G16="","Handmatig beoordelen",IF($G16>=4,"A-staal",IF($G16>=2,"B-staal",IF($G16>0,"C-staal","Handmatig beoordelen")))))) -> B-staal | M16: =IFERROR(Tabel2640[[#This Row],[BIM-volume m³]]*INDEX(Tabel17[CO2-nieuw (kg)],1)+Tabel2640[[#This Row],[BIM-volume m³]]*Tabel2640[[#This Row],[Transport Impact]]*IF(Tabel2640[[#This Row],[Transportafstand (km)]]="",0,Tabel2640[[#This Row],[Transportafstand (km)]]),0) -> 0 | N16: =IFERROR(Tabel2640[[#This Row],[BIM-volume m³]]*INDEX(Tabel17[CO2-Hergebruik (kg)],1)+Tabel2640[[#This Row],[BIM-volume m³]]*Tabel2640[[#This Row],[Transportafstand (km)]]*Tabel2640[[#This Row],[Transport Impact]],0) -> 0 | O16: =IFERROR(Tabel2640[[#This Row],[BIM-volume m³]]*Staal!$O$3+Tabel2640[[#This Row],[BIM-volume m³]]*Tabel2640[[#This Row],[Transport Impact]]*IF(Tabel2640[[#This Row],[Transportafstand (km)]]="",0,Tabel2640[[#This Row],[Transportafstand (km)]]),0) -> 0 | P16: =IFERROR(MAX(0,Tabel2640[[#This Row],[Tot. nieuw CO2 (kg)]]-MIN(IF(Tabel2640[[#This Row],[Tot. hergebruik CO2 (kg)]]=0,999999,Tabel2640[[#This Row],[Tot. hergebruik CO2 (kg)]]),IF(Tabel2640[[#This Row],[Tot. recycling Co2 (kg)]]=0,999999,Tabel2640[[#This Row],[Tot. recycling Co2 (kg)]]))),0) -> 0 | Q16: =IF(OR($M15="",$M15=0),"Geen beoordeling",IF(AND($N16=0,$O16=0),"Geen beoordeling",IF($N16<$O16,"Hergebruik",IF($O16<$N16,"Recycling","Hergebruik en recycling gelijk")))) -> Geen beoordeling | R16: =IFERROR(Tabel2640[[#This Row],[BIM-volume m³]]*Tabel2640[[#This Row],[PRR]],0) -> 0 | S16: =IFERROR(VLOOKUP(Tabel2640[[#This Row],[Klasse]],Staal!$A$10:$D$13,4,FALSE),0) -> 150 | T16: =Tabel2640[[#This Row],[Praktisch terugwinbaar volume m³]]*Tabel2640[[#This Row],[Verkoopprijs per m³]] -> 0 | U16: =IF(OR($L16="Handmatig beoordelen",$L16="",$L16="Totaal",$I16=""),"Handmatig",IF($I16>=70%,"Ja","Nee")) -> Nee | V16: =IF(OR($L16="Handmatig beoordelen",$L16="",$L16="Totaal",$Q16=""),"Handmatig",IF(OR($Q16="Hergebruik",$Q16="Recycling",$Q16="Hergebruik en recycling",$Q16="Hergebruik en recycling gelijk"),"Ja","Nee")) -> Nee | W16: =IF(OR($L16="Handmatig beoordelen",$L16="",$L16="Totaal"),"Handmatig",IF($T16>0,"Ja","Nee")) -> Nee | X16: =IF(OR($U16="Handmatig",$V16="Handmatig",$W16="Handmatig"),"Handmatig beoordelen",IF(COUNTIF($U16:$W16,"Ja")>=2,"Interessant",IF(COUNTIF($U16:$W16,"Ja")=1,"Eigen beoordeling","Niet interessant"))) -> Niet interessant
A17: Staal | B17: Kolommen | C17: ='Staal-data'!B4 -> 0 | D17: 4 | E17: 20 | F17: 1 | G17: 3 | H17: 3 | I17: =IFERROR(ROUND(AVERAGE(Tabel2640[[#This Row],[Demonteerbaarheid]],Tabel2640[[#This Row],[Materiaalconditie ]],Tabel2640[[#This Row],[Marktpotentie ]])/5,2),0) -> 0.47 | J17: =IF(Tabel2640[[#This Row],[PRR]]="","Handmatig beoordelen",IF(Tabel2640[[#This Row],[PRR]]>=0.75,"Hergebruik",IF(Tabel2640[[#This Row],[PRR]]>=0.4,"Hergebruik > recycling",IF(Tabel2640[[#This Row],[PRR]]>=0.15,"Recycling","Handmatig beoordelen")))) -> Hergebruik > recycling | K17: =IF(Tabel2640[[#This Row],[Routeadvies]]="Hergebruik",">= 0,75",IF(Tabel2640[[#This Row],[Routeadvies]]="Hergebruik > recycling",">= 0,4 en < 0,75",IF(Tabel2640[[#This Row],[Routeadvies]]="Recycling",">= 0,15 en < 0,4",IF(Tabel2640[[#This Row],[Routeadvies]]="Handmatig beoordelen","< 0,15 of geen score","")))) -> >= 0,4 en < 0,75 | L17: =IF($B17="Totaal","Totaal",IF(OR($B17="deuren",$B17="Balken",$B17="Liggers",$B17="Buisstaalconstructies",$B17="Kozijnen",$B17="Trappen",$B17="Hekwerken",$B17="Leuningen",$B17="ramen"),"Bijzonder staal",IF($G17="","Handmatig beoordelen",IF($G17>=4,"A-staal",IF($G17>=2,"B-staal",IF($G17>0,"C-staal","Handmatig beoordelen")))))) -> B-staal | M17: =IFERROR(Tabel2640[[#This Row],[BIM-volume m³]]*INDEX(Tabel17[CO2-nieuw (kg)],1)+Tabel2640[[#This Row],[BIM-volume m³]]*Tabel2640[[#This Row],[Transport Impact]]*IF(Tabel2640[[#This Row],[Transportafstand (km)]]="",0,Tabel2640[[#This Row],[Transportafstand (km)]]),0) -> 0 | N17: =IFERROR(Tabel2640[[#This Row],[BIM-volume m³]]*INDEX(Tabel17[CO2-Hergebruik (kg)],1)+Tabel2640[[#This Row],[BIM-volume m³]]*Tabel2640[[#This Row],[Transportafstand (km)]]*Tabel2640[[#This Row],[Transport Impact]],0) -> 0 | O17: =IFERROR(Tabel2640[[#This Row],[BIM-volume m³]]*Staal!$O$3+Tabel2640[[#This Row],[BIM-volume m³]]*Tabel2640[[#This Row],[Transport Impact]]*IF(Tabel2640[[#This Row],[Transportafstand (km)]]="",0,Tabel2640[[#This Row],[Transportafstand (km)]]),0) -> 0 | P17: =IFERROR(MAX(0,Tabel2640[[#This Row],[Tot. nieuw CO2 (kg)]]-MIN(IF(Tabel2640[[#This Row],[Tot. hergebruik CO2 (kg)]]=0,999999,Tabel2640[[#This Row],[Tot. hergebruik CO2 (kg)]]),IF(Tabel2640[[#This Row],[Tot. recycling Co2 (kg)]]=0,999999,Tabel2640[[#This Row],[Tot. recycling Co2 (kg)]]))),0) -> 0 | Q17: =IF(OR($M16="",$M16=0),"Geen beoordeling",IF(AND($N17=0,$O17=0),"Geen beoordeling",IF($N17<$O17,"Hergebruik",IF($O17<$N17,"Recycling","Hergebruik en recycling gelijk")))) -> Geen beoordeling | R17: =IFERROR(Tabel2640[[#This Row],[BIM-volume m³]]*Tabel2640[[#This Row],[PRR]],0) -> 0 | S17: =IFERROR(VLOOKUP(Tabel2640[[#This Row],[Klasse]],Staal!$A$10:$D$13,4,FALSE),0) -> 150 | T17: =Tabel2640[[#This Row],[Praktisch terugwinbaar volume m³]]*Tabel2640[[#This Row],[Verkoopprijs per m³]] -> 0 | U17: =IF(OR($L17="Handmatig beoordelen",$L17="",$L17="Totaal",$I17=""),"Handmatig",IF($I17>=70%,"Ja","Nee")) -> Nee | V17: =IF(OR($L17="Handmatig beoordelen",$L17="",$L17="Totaal",$Q17=""),"Handmatig",IF(OR($Q17="Hergebruik",$Q17="Recycling",$Q17="Hergebruik en recycling",$Q17="Hergebruik en recycling gelijk"),"Ja","Nee")) -> Nee | W17: =IF(OR($L17="Handmatig beoordelen",$L17="",$L17="Totaal"),"Handmatig",IF($T17>0,"Ja","Nee")) -> Nee | X17: =IF(OR($U17="Handmatig",$V17="Handmatig",$W17="Handmatig"),"Handmatig beoordelen",IF(COUNTIF($U17:$W17,"Ja")>=2,"Interessant",IF(COUNTIF($U17:$W17,"Ja")=1,"Eigen beoordeling","Niet interessant"))) -> Niet interessant | Y17: 530
